<?xml version="1.0"?>

<robot xmlns:xacro="http://www.ros.org/wiki/xacro" 
    xmlns:sensor="http://playerstage.sourceforge.net/gazebo/xmlschema/#sensor"
        xmlns:controller="http://playerstage.sourceforge.net/gazebo/xmlschema/#controller"
        xmlns:interface="http://playerstage.sourceforge.net/gazebo/xmlschema/#interface"
    name="robot1_xacro">


    <xacro:property name="length_wheel" value="0.05" />
    <xacro:property name="radius_wheel" value="0.05" />
    <xacro:macro name="default_inertial" params="mass">
               <inertial>
                       <mass value="${mass}" />
                       <inertia ixx="1.0" ixy="0.0" ixz="0.0"
                                iyy="1.0" iyz="0.0"
                                izz="1.0" />
               </inertial>
    </xacro:macro>

     <link name="base_link">
        <visual>
            <geometry>
                    <box size="0.3 0.2 0.1"/>
                </geometry>
            <origin rpy="0 0 0" xyz="0 0 0"/>
            <material name="white">
                <color rgba="1 1 1 1"/>
            </material>
        </visual>
        <collision>
            <geometry>
                    <box size="0.3 0.2 0.1"/>
            </geometry>
        </collision>
        <xacro:default_inertial mass="10"/>
    </link>

    <gazebo reference="base_link">
        <material>Gazebo/Green</material>
        <turnGravityOff>false</turnGravityOff>
    </gazebo> 
  
    <link name="laser_link">
        <visual>
            <geometry>
                    <box size="0.05 0.05 0.1"/>
                </geometry>
            <origin rpy="0 0 0" xyz="0 0 0"/>
            <material name="white">
                <color rgba="1 1 1 1"/>
            </material>
        </visual>
        <collision>
            <geometry>
                    <box size="0.05 0.05 0.1"/>
            </geometry>
        </collision>
        <xacro:default_inertial mass="1"/>
    </link>

    <gazebo reference="laser_link">
        <material>Gazebo/Blue</material>
        <turnGravityOff>false</turnGravityOff>
    </gazebo>

    <link name="bumper_link">
        <visual>
            <geometry>
                    <box size="0.05 0.1 0.05"/>
                </geometry>
            <origin rpy="0 0 0" xyz="0 0 0"/>
            <material name="white">
                <color rgba="1 1 1 1"/>
            </material>
        </visual>
        <collision name="bumper">
            <geometry>
                    <box size="0.05 0.1 0.05"/>
            </geometry>
        </collision>
        <xacro:default_inertial mass="1"/>
    </link>

    <gazebo reference="bumper_link">
        <material>Gazebo/Orange</material>
        <turnGravityOff>false</turnGravityOff>
    </gazebo>

    <link name="wheel_1">
        <visual>
                <geometry>
                    <cylinder length="${length_wheel}" radius="${radius_wheel}"/>
                </geometry>
            <origin rpy="0 0 0" xyz="0 0 0"/>
            <material name="black">
                <color rgba="0 0 0 1"/>
            </material>
        </visual>
        <collision>
            <geometry>
                    <cylinder length="${length_wheel}" radius="${radius_wheel}"/>
            </geometry>
        </collision>
        <xacro:default_inertial mass="1"/>
    </link>
    <gazebo reference="wheel_1">
        <material>Gazebo/black</material>
        <turnGravityOff>false</turnGravityOff>
    </gazebo>
    <link name="wheel_2">
        <visual>
                <geometry>
                    <cylinder length="${length_wheel}" radius="${radius_wheel}"/>
                </geometry>
            <origin rpy="0 0 0" xyz="0 0 0"/>
            <material name="black"/>
        </visual>
        <collision>
            <geometry>
                    <cylinder length="${length_wheel}" radius="${radius_wheel}"/>
            </geometry>
        </collision>
        <xacro:default_inertial mass="1"/>

    </link>
    <gazebo reference="wheel_2">
        <material>Gazebo/black</material>
        <turnGravityOff>false</turnGravityOff>
    </gazebo>
    <link name="wheel_3">
        <visual>
                <geometry>
                    <cylinder length="${length_wheel}" radius="${radius_wheel}"/>
                </geometry>

            <origin rpy="0 0 0" xyz="0 0 0"/>
            <material name="black"/>
        </visual>
        <collision>
            <geometry>
                    <cylinder length="${length_wheel}" radius="${radius_wheel}"/>
            </geometry>
        </collision>
        <xacro:default_inertial mass="1"/>
    </link>
    <gazebo reference="wheel_3">
        <material>Gazebo/black</material>
        <turnGravityOff>false</turnGravityOff>
    </gazebo>
    <link name="wheel_4">
        <visual>
                <geometry>
                    <cylinder length="${length_wheel}" radius="${radius_wheel}"/>
                </geometry>
            <origin rpy="0 0 0" xyz="0 0 0" />
            <material name="black"/>
        </visual>
        <collision>
            <geometry>
                    <cylinder length="${length_wheel}" radius="${radius_wheel}"/>
            </geometry>
        </collision>
        <xacro:default_inertial mass="1"/>
    </link>
    <gazebo reference="wheel_4">
        <material>Gazebo/black</material>
        <turnGravityOff>false</turnGravityOff>
    </gazebo>

    <joint name="base_to_laser" type="fixed">
        <parent link="base_link"/>
        <child link="laser_link"/>
        <origin rpy="0 0 0" xyz="0.0 0.0 0.1"/>
        <axis xyz="0 0 1"/>
    </joint>
    
    <joint name="base_to_bumper" type="fixed">
        <parent link="base_link"/>
        <child link="bumper_link"/>
        <origin rpy="0 0 0" xyz="0.175 0.0 0.0"/>
        <axis xyz="0 0 1"/>
    </joint>
    
    <joint name="base_to_wheel1" type="continuous">
        <parent link="base_link"/>
        <child link="wheel_1"/>
        <origin rpy="-1.5707 0 0" xyz="0.1 0.15 0"/>
        <axis xyz="0 0 1"/>
        <limit effort="100" velocity="100" />
    </joint>
    
    <joint name="base_to_wheel2" type="continuous">
        <axis xyz="0 0 1" />
        <limit effort="100" velocity="100" />
        <parent link="base_link"/>
   	<child link="wheel_2"/>
   	<origin rpy="-1.5707 0 0" xyz="-0.1 0.15 0"/>
    </joint>

    <joint name="base_to_wheel3" type="continuous">
        <parent link="base_link"/>
   	<axis xyz="0 0 1" />
   	<child link="wheel_3"/>
   	<origin rpy="-1.5707 0 0" xyz="0.1 -0.15 0"/>
    </joint>

    <joint name="base_to_wheel4" type="continuous">
       <parent link="base_link"/>
   	<axis xyz="0 0 1" />
   	<child link="wheel_4"/>
   	<origin rpy="-1.5707 0 0" xyz="-0.1 -0.15 0"/>
    </joint>
    
    <gazebo>
        <plugin name="skid_steer_drive_controller" filename="libgazebo_ros_skid_steer_drive.so">
    	    <alwaysOn>true</alwaysOn>
    	    <updateRate>100.0</updateRate>
    	    <robotNamespace>/</robotNamespace>
    	    <leftFrontJoint>base_to_wheel1</leftFrontJoint>
    	    <rightFrontJoint>base_to_wheel3</rightFrontJoint>
    	    <leftRearJoint>base_to_wheel2</leftRearJoint>
    	    <rightRearJoint>base_to_wheel4</rightRearJoint>
    	    <wheelSeparation>0.2</wheelSeparation>
    	    <wheelDiameter>0.1</wheelDiameter>
    	    <torque>2</torque>
    	    <commandTopic>cmd_vel</commandTopic>
    	    <robotBaseFrame>base_link</robotBaseFrame>
    	    <broadcastTF>1</broadcastTF>
        </plugin>
    </gazebo>

    <gazebo reference="laser_link">
        <sensor type="ray" name="head_hokuyo_sensor">
            <pose>0 0 0.1 0 0 0</pose>
            <visualize>true</visualize>
            <update_rate>1</update_rate>
            <ray>
                <scan>
                    <horizontal>
                        <samples>100</samples>
           	        <resolution>1</resolution>
                        <min_angle>-1.570796</min_angle>
                        <max_angle>1.570796</max_angle>
                    </horizontal>
        	</scan>
                <range>
                    <min>0.10</min>
                    <max>5.0</max>
                    <resolution>0.1</resolution>
                </range>
                <noise>
                    <type>gaussian</type>
                    <mean>0.0</mean>
                    <stddev>0.01</stddev>
                </noise>
            </ray>
            <plugin name="gazebo_ros_head_hokuyo_controller" filename="libgazebo_ros_laser.so">
                <topicName>/robottest/scan</topicName>
                <frameName>laser_link</frameName>
            </plugin>
        </sensor>
    </gazebo>

    <gazebo reference="bumper_link">
      <sensor name="pressure_sensor" type="contact">
        <always_on>1</always_on>
        <update_rate>1</update_rate>
        <visualize>true</visualize>
        <contact>
               <collision>base_link_fixed_joint_lump__bumper_collision_1</collision>
        </contact>
        <plugin name="robottest_gazebo_ros_bumper_controller" filename="libgazebo_ros_bumper.so">
            <alwaysOn>1</alwaysOn>
            <updateRate>1</updateRate>
            <bumperTopicName>/robottest/bumper</bumperTopicName>
            <frameName>bumper_link</frameName>
        </plugin>
      </sensor>
      <material>Gazebo/Orange</material>
    </gazebo>


</robot>

